<robot name="PF3400SX Robot">

  <!-- Materials -->

  <material name="white">
    <color rgba="1 1 1 1"/>
  </material>

  <material name="aluminum">
    <color rgba="0.6 0.6 0.6 1"/>
  </material>



  <!-- Links -->

  <link name="z_column">
    <visual>
      <origin xyz="0 0 0" rpy="0 0 0"/>
      <geometry>
        <mesh filename="package://pa_viz_pf3400/urdf/mesh/PF3400_Z_Column.STL" scale="0.001 0.001 0.001"/>
      </geometry>
      <material name="white"/>
    </visual>
  </link>

  <link name="z_carriage">
    <visual>
      <origin xyz="0 0 0" rpy="0 0 0"/>
      <geometry>
        <mesh filename="package://pa_viz_pf3400/urdf/mesh/PF3400_Z_Carriage.STL" scale="0.001 0.001 0.001"/>
      </geometry>
      <material name="white"/>
    </visual>
  </link>

  <link name="inner_link">
    <visual>
      <origin xyz="0 0 0" rpy="0 0 0"/>
      <geometry>
        <mesh filename="package://pa_viz_pf3400/urdf/mesh/PF3400_Inner_Link.STL" scale="0.001 0.001 0.001"/>
      </geometry>
      <material name="white"/>
    </visual>
  </link>

  <link name="outer_link">
    <visual>
      <origin xyz="0 0 0" rpy="0 0 0"/>
      <geometry>
        <mesh filename="package://pa_viz_pf3400/urdf/mesh/PF3400_Outer_Link.STL" scale="0.001 0.001 0.001"/>
      </geometry>
      <material name="white"/>
    </visual>
  </link>

  <link name="hand">
    <visual>
      <origin xyz="0 0 0" rpy="0 0 0"/>
      <geometry>
        <mesh filename="package://pa_viz_pf3400/urdf/mesh/PF3400_Hand.STL" scale="0.001 0.001 0.001"/>
      </geometry>
      <material name="white"/>
    </visual>
  </link>

  <link name="left_finger">
    <visual>
      <origin xyz="0 0 0" rpy="0 0 0"/>
      <geometry>
        <mesh filename="package://pa_viz_pf3400/urdf/mesh/PF3400_Left_Finger.STL" scale="0.001 0.001 0.001"/>
      </geometry>
      <material name="aluminum"/>
    </visual>
  </link>

  <link name="right_finger">
    <visual>
      <origin xyz="0 0 0" rpy="0 0 0"/>
      <geometry>
        <mesh filename="package://pa_viz_pf3400/urdf/mesh/PF3400_Right_Finger.STL" scale="0.001 0.001 0.001"/>
      </geometry>
      <material name="aluminum"/>
    </visual>
  </link>


  <!-- Joints -->

  <joint name="J1" type="prismatic">
    <parent link="z_column"/>
    <child link="z_carriage"/>
    <axis xyz="0 0 1"/>
    <origin xyz="0.03005 -0.0198 0.17535" rpy="0 0 0"/>
    <limit effort="1000.0" lower="0.0015" upper="0.4015" velocity="0.5"/>
  </joint>

  <joint name="J2" type="revolute">
    <parent link="z_carriage"/>
    <child link="inner_link"/>
    <axis xyz="0 0 1"/>
    <origin xyz="0.173001 0.020 .0235" rpy="0 0 0"/>
    <limit effort="1000.0" lower="-1.62316" upper="1.62316" velocity="0.5"/>
  </joint>

  <joint name="J3" type="revolute">
    <parent link="inner_link"/>
    <child link="outer_link"/>
    <axis xyz="0 0 1"/>
    <origin xyz="0.302 0 -0.072285" rpy="0 0 0"/>
    <limit effort="1000.0" lower="0.20944" upper="6.07375" velocity="0.5"/>
  </joint>

  <joint name="J4" type="revolute">
    <parent link="outer_link"/>
    <child link="hand"/>
    <axis xyz="0 0 1"/>
    <origin xyz="0.289 0 -0.032942" rpy="0 0 0"/>
    <limit effort="1000.0" lower="-16.7552" upper="16.7552" velocity="0.5"/>
  </joint>

  <joint name="J5" type="prismatic">
    <parent link="hand"/>
    <child link="left_finger"/>
    <axis xyz="0 1 0"/>
    <origin xyz="0.078573 0 -0.04269" rpy="0 0 0"/>
    <limit effort="1000.0" lower="0.051954" upper="0.070" velocity="0.5"/>
  </joint>

  <joint name="J5_mirror" type="prismatic">
    <parent link="hand"/>
    <child link="right_finger"/>
    <axis xyz="0 -1 0"/>
    <origin xyz="0.078573 0 -0.04269" rpy="0 0 0"/>
    <limit effort="1000.0" lower="0.051954" upper="0.070" velocity="0.5"/>
    <mimic joint="J5" multiplier="1"/>
  </joint>

</robot>
